Workbook
Name FromArray_1: _xlfn.ANCHORARRAY('Лист1 (2)'!$A$32)
Name FromArray_1: _xlfn.ANCHORARRAY(Лист1!$B$32)

Sheet Лист1
A1: model,class_name,iou,dice,precision,recall | B1: {=_xlfn.TEXTSPLIT(A1,",")} -> model | C1: class_name | D1: iou | E1: dice | F1: precision | G1: recall
A2: Deeplab_DICE_1_Fold_2,drusen,0.33971188298597094,0.5071417030784496,0.5848729944061479,0.44764800478042593 | B2: Deeplab_DICE_1_Fold_2 | C2: drusen | D2: 0.33971188298597094 | E2: 0.5071417030784496 | F2: 0.5848729944061479 | G2: 0.44764800478042593
A3: Deeplab_DICE_1_Fold_2,edema,0.3693288017904073,0.5394304148244121,0.5443597881058019,0.5345895148742104 | C3: edema | D3: 0.3693288017904073 | E3: 0.5394304148244121 | F3: 0.5443597881058019 | G3: 0.5345895148742104
A4: Deeplab_DICE_1_Fold_2,epiretinal_fibrosis,0.6137082691206436,0.7606186085358179,0.7017354672943479,0.8302887507165216 | C4: epiretinal_fibrosis | D4: 0.6137082691206436 | E4: 0.7606186085358179 | F4: 0.7017354672943479 | G4: 0.8302887507165216
A5: Deeplab_DICE_1_Fold_2,fibrosis,0.3291532818748906,0.4952826530444859,0.62144706560015,0.4117004090632765 | C5: fibrosis | D5: 0.3291532818748906 | E5: 0.4952826530444859 | F5: 0.62144706560015 | G5: 0.4117004090632765
A6: Deeplab_DICE_1_Fold_2,geographic_atrophy,0.7164491782666792,0.8348038349613948,0.8118167367726684,0.8591306563483639 | C6: geographic_atrophy | D6: 0.7164491782666792 | E6: 0.8348038349613948 | F6: 0.8118167367726684 | G6: 0.8591306563483639
A7: Deeplab_DICE_1_Fold_2,hard_exudates,0.5827032418924245,0.7363392283138199,0.7252271738487628,0.7477971030845335 | C7: hard_exudates | D7: 0.5827032418924245 | E7: 0.7363392283138199 | F7: 0.7252271738487628 | G7: 0.7477971030845335
A8: Deeplab_DICE_1_Fold_2,hemorrhages,0.5446580654161489,0.7052150603563018,0.7274888913360983,0.684264644189612 | C8: hemorrhages | D8: 0.5446580654161489 | E8: 0.7052150603563018 | F8: 0.7274888913360983 | G8: 0.684264644189612
A9: Deeplab_DICE_1_Fold_2,laser_coagulates,0.5413566012522176,0.7024417332269672,0.6094202882712776,0.8289759922938681 | C9: laser_coagulates | D9: 0.5413566012522176 | E9: 0.7024417332269672 | F9: 0.6094202882712776 | G9: 0.8289759922938681
A10: Deeplab_DICE_1_Fold_2,macular_hole,0.7263737540369236,0.8415023135498712,0.7454420884127951,0.9659820784836819 | C10: macular_hole | D10: 0.7263737540369236 | E10: 0.8415023135498712 | F10: 0.7454420884127951 | G10: 0.9659820784836819
A11: Deeplab_DICE_1_Fold_2,microaneurysms,0.16201700656473286,0.2788547941199298,0.3134902605246136,0.25111117994126536 | C11: microaneurysms | D11: 0.16201700656473286 | E11: 0.2788547941199298 | F11: 0.3134902605246136 | G11: 0.25111117994126536
A12: Deeplab_DICE_1_Fold_2,neovascularization,0.5859510628060817,0.7389270407490844,0.6742725887017316,0.8172956457003497 | C12: neovascularization | D12: 0.5859510628060817 | E12: 0.7389270407490844 | F12: 0.6742725887017316 | G12: 0.8172956457003497
A13: Deeplab_DICE_1_Fold_2,soft_exudates,0.3201113912989254,0.48497633367734433,0.7147916020568866,0.366985485029057 | C13: soft_exudates | D13: 0.3201113912989254 | E13: 0.48497633367734433 | F13: 0.7147916020568866 | G13: 0.366985485029057
A14: Deeplab_DICE_1_Fold_2,subretinal_hemorrhage,0.4988901404682895,0.6656793943716571,0.6453709029271021,0.6873075454763514 | C14: subretinal_hemorrhage | D14: 0.4988901404682895 | E14: 0.6656793943716571 | F14: 0.6453709029271021 | G14: 0.6873075454763514
... A16: Deeplab_DICE_1_Fold_2,MEAN,0.46134664184725327,0.6084896640532546,0.6241970188003876,0.6150023141086933 | C16: MEAN | D16: 0.46134664184725327 | E16: 0.6084896640532546 | F16: 0.6241970188003876 | G16: 0.6150023141086933
A17: Deeplab_DICE_2_Fold_3,drusen,0.3621915248181946,0.5317776806261287,0.5780655108823661,0.49235315385095235 | B17: Deeplab_DICE_2_Fold_3 | C17: drusen | D17: 0.3621915248181946 | E17: 0.5317776806261287 | F17: 0.5780655108823661 | G17: 0.49235315385095235
A18: Deeplab_DICE_2_Fold_3,edema,0.3054680865941911,0.46798246503462304,0.47158010680510387,0.46443929983147714 | C18: edema | D18: 0.3054680865941911 | E18: 0.46798246503462304 | F18: 0.47158010680510387 | G18: 0.46443929983147714
A19: Deeplab_DICE_2_Fold_3,epiretinal_fibrosis,0.6216374944141824,0.7666787386890673,0.7089558176377939,0.8346343603061547 | C19: epiretinal_fibrosis | D19: 0.6216374944141824 | E19: 0.7666787386890673 | F19: 0.7089558176377939 | G19: 0.8346343603061547
A20: Deeplab_DICE_2_Fold_3,fibrosis,0.3979541008227535,0.5693378639377947,0.5534701580470819,0.5861422623202275 | C20: fibrosis | D20: 0.3979541008227535 | E20: 0.5693378639377947 | F20: 0.5534701580470819 | G20: 0.5861422623202275
A21: Deeplab_DICE_2_Fold_3,geographic_atrophy,0.7457835414429911,0.8543826009799106,0.8039878470078181,0.9115174146775376 | C21: geographic_atrophy | D21: 0.7457835414429911 | E21: 0.8543826009799106 | F21: 0.8039878470078181 | G21: 0.9115174146775376
A22: Deeplab_DICE_2_Fold_3,hard_exudates,0.5686237591737634,0.7249969992463621,0.7710495788096041,0.6841355455728078 | C22: hard_exudates | D22: 0.5686237591737634 | E22: 0.7249969992463621 | F22: 0.7710495788096041 | G22: 0.6841355455728078
A23: Deeplab_DICE_2_Fold_3,hemorrhages,0.5273784571199511,0.6905668397528458,0.692953002666861,0.688197053806307 | C23: hemorrhages | D23: 0.5273784571199511 | E23: 0.6905668397528458 | F23: 0.692953002666861 | G23: 0.688197053806307
A24: Deeplab_DICE_2_Fold_3,laser_coagulates,0.6012587492164639,0.7509826247765077,0.7343530850308841,0.768382772074196 | C24: laser_coagulates | D24: 0.6012587492164639 | E24: 0.7509826247765077 | F24: 0.7343530850308841 | G24: 0.768382772074196
A25: Deeplab_DICE_2_Fold_3,macular_hole,0.8041546441752276,0.8914475782566282,0.8110512500351023,0.9895364434021147 | C25: macular_hole | D25: 0.8041546441752276 | E25: 0.8914475782566282 | F25: 0.8110512500351023 | G25: 0.9895364434021147
A26: Deeplab_DICE_2_Fold_3,microaneurysms,0.13451248083758302,0.23712825219564923,0.3513789195311027,0.17894453315878245 | C26: microaneurysms | D26: 0.13451248083758302 | E26: 0.23712825219564923 | F26: 0.3513789195311027 | G26: 0.17894453315878245
A27: Deeplab_DICE_2_Fold_3,neovascularization,0.5757599476252869,0.7307711412426401,0.6302798724209823,0.8693851444559875 | C27: neovascularization | D27: 0.5757599476252869 | E27: 0.7307711412426401 | F27: 0.6302798724209823 | G27: 0.8693851444559875
A28: Deeplab_DICE_2_Fold_3,soft_exudates,0.491122187351457,0.6587282940558911,0.6414072089584972,0.6770108489808212 | C28: soft_exudates | D28: 0.491122187351457 | E28: 0.6587282940558911 | F28: 0.6414072089584972 | G28: 0.6770108489808212
A29: Deeplab_DICE_2_Fold_3,subretinal_hemorrhage,0.4793923677514781,0.6480936068098072,0.6711221017894428,0.6265930557186965 | C29: subretinal_hemorrhage | D29: 0.4793923677514781 | E29: 0.6480936068098072 | F29: 0.6711221017894428 | G29: 0.6265930557186965
... A31: Deeplab_DICE_2_Fold_3,MEAN,0.49407729177205945,0.6418995129972379,0.6342575856216344,0.6599156676175658 | C31: MEAN | D31: 0.49407729177205945 | E31: 0.6418995129972379 | F31: 0.6342575856216344 | G31: 0.6599156676175658
A32: Deeplab_DICE_3_Fold_1,drusen,0.3694523303849434,0.5395621624610956,0.5833288373947557,0.5019046743963665 | B32: Deeplab_DICE_3_Fold_1 | C32: drusen | D32: 0.3694523303849434 | E32: 0.5395621624610956 | F32: 0.5833288373947557 | G32: 0.5019046743963665
A33: Deeplab_DICE_3_Fold_1,edema,0.4126395990972416,0.5842107206409083,0.5817374583864957,0.5867051028824327 | C33: edema | D33: 0.4126395990972416 | E33: 0.5842107206409083 | F33: 0.5817374583864957 | G33: 0.5867051028824327
A34: Deeplab_DICE_3_Fold_1,epiretinal_fibrosis,0.6040734152080894,0.753174274295576,0.6939384989755969,0.8234668072029407 | C34: epiretinal_fibrosis | D34: 0.6040734152080894 | E34: 0.753174274295576 | F34: 0.6939384989755969 | G34: 0.8234668072029407
A35: Deeplab_DICE_3_Fold_1,fibrosis,0.3910137793763179,0.5621997210575942,0.6067643155486369,0.5237334374246658 | C35: fibrosis | D35: 0.3910137793763179 | E35: 0.5621997210575942 | F35: 0.6067643155486369 | G35: 0.5237334374246658
A36: Deeplab_DICE_3_Fold_1,geographic_atrophy,0.7910831328051496,0.8833572471492991,0.825612533552015,0.9497869241264179 | C36: geographic_atrophy | D36: 0.7910831328051496 | E36: 0.8833572471492991 | F36: 0.825612533552015 | G36: 0.9497869241264179
A37: Deeplab_DICE_3_Fold_1,hard_exudates,0.49878937317280664,0.665589684715889,0.7170499354100253,0.6210210990884784 | C37: hard_exudates | D37: 0.49878937317280664 | E37: 0.665589684715889 | F37: 0.7170499354100253 | G37: 0.6210210990884784
A38: Deeplab_DICE_3_Fold_1,hemorrhages,0.5801116886352681,0.7342666886241525,0.7969239062759599,0.6807439826887607 | C38: hemorrhages | D38: 0.5801116886352681 | E38: 0.7342666886241525 | F38: 0.7969239062759599 | G38: 0.6807439826887607
A39: Deeplab_DICE_3_Fold_1,laser_coagulates,0.6459400149853316,0.7848888891507848,0.7217445790322587,0.8601413142778727 | C39: laser_coagulates | D39: 0.6459400149853316 | E39: 0.7848888891507848 | F39: 0.7217445790322587 | G39: 0.8601413142778727
A40: Deeplab_DICE_3_Fold_1,macular_hole,0.7510269664504345,0.8578131357655404,0.7664014662388685,0.9739839745901071 | C40: macular_hole | D40: 0.7510269664504345 | E40: 0.8578131357655404 | F40: 0.7664014662388685 | G40: 0.9739839745901071
A41: Deeplab_DICE_3_Fold_1,microaneurysms,0.15356190634887787,0.26623955854248765,0.34217048650724313,0.2178880915505823 | C41: microaneurysms | D41: 0.15356190634887787 | E41: 0.26623955854248765 | F41: 0.34217048650724313 | G41: 0.2178880915505823
A42: Deeplab_DICE_3_Fold_1,neovascularization,0.5956591519783816,0.746599486788707,0.7040516371529165,0.7946206822851979 | C42: neovascularization | D42: 0.5956591519783816 | E42: 0.746599486788707 | F42: 0.7040516371529165 | G42: 0.7946206822851979
...

Sheet Лист1 (2)
A1: model | B1: class_name | C1: iou | D1: dice | E1: precision | F1: recall | H1: DICE | P1: MEAN
A2: Deeplab_DICE_1_Fold_2 | B2: drusen | C2: 0.33971188 | D2: 0.5071417 | E2: 0.58487299 | F2: 0.447648 | H2: model | I2: mean | J2: std | K2: t стьюдент | L2: нижняя граница | M2: верхняя граница | P2: iou | Q2: dice | R2: precision | S2: recall | V2: iou | W2: dice | X2: precision | Y2: recall
B3: edema | C3: 0.3693288 | D3: 0.53943041 | E3: 0.54435979 | F3: 0.53458951 | H3: Deeplab DICE | I3: =AVERAGE(D2:D15,D17:D30,D32:D45) -> 0.62677504 | J3: =_xlfn.STDEV.S(D2:D15,D17:D30,D32:D45) -> 0.19453525 | K3: =_xlfn.CONFIDENCE.T(0.05, J3, 42) -> 0.06062145 | L3: =I3-K3 -> 0.56615359 | M3: =I3+K3 -> 0.68739649 | O3: Deeplab_DICE_1_Fold_2 | P3: 0.46134664 | Q3: 0.60848966 | R3: 0.62419702 | S3: 0.61500231 | U3: Deeplab DICE | V3: =AVERAGE(P3:P5) -> 0.48235261 | W3: =AVERAGE(Q3:Q5) -> 0.62677504 | X3: =AVERAGE(R3:R5) -> 0.64535183 | Y3: =AVERAGE(S3:S5) -> 0.63652624
B4: epiretinal_fibrosis | C4: 0.61370827 | D4: 0.76061861 | E4: 0.70173547 | F4: 0.83028875 | H4: Deeplab Tversky | I4: =AVERAGE(D47:D60,D62:D75,D77:D90) -> 0.63309322 | J4: =_xlfn.STDEV.S(D47:D60,D62:D75,D77:D90) -> 0.20047826 | K4: =_xlfn.CONFIDENCE.T(0.05, J4, 42) -> 0.062473424 | L4: =I4-K4 -> 0.57061979 | M4: =I4+K4 -> 0.69556664 | O4: Deeplab_DICE_2_Fold_3 | P4: 0.49407729 | Q4: 0.64189951 | R4: 0.63425759 | S4: 0.65991567 | U4: Deeplab Tversky | V4: =AVERAGE(P6:P8) -> 0.49060028 | W4: =AVERAGE(Q6:Q8) -> 0.63309322 | X4: =AVERAGE(R6:R8) -> 0.62647291 | Y4: =AVERAGE(S6:S8) -> 0.64843435
B5: fibrosis | C5: 0.32915328 | D5: 0.49528265 | E5: 0.62144707 | F5: 0.41170041 | H5: TransUNet DICE | I5: =AVERAGE(D92:D105,D107:D120,D122:D135) -> 0.55687483 | J5: =_xlfn.STDEV.S(D92:D105,D107:D120,D122:D135) -> 0.27057601 | K5: =_xlfn.CONFIDENCE.T(0.05, J5, 42) -> 0.08431742 | L5: =I5-K5 -> 0.47255741 | M5: =I5+K5 -> 0.64119225 | O5: Deeplab_DICE_3_Fold_1 | P5: 0.4916339 | Q5: 0.62993595 | R5: 0.6776009 | S5: 0.63466073 | U5: TransUNet DICE | V5: =AVERAGE(P9:P11) -> 0.42794432 | W5: =AVERAGE(Q9:Q11) -> 0.55687483 | X5: =AVERAGE(R9:R11) -> 0.54332935 | Y5: =AVERAGE(S9:S11) -> 0.57794372
B6: geographic_atrophy | C6: 0.71644918 | D6: 0.83480383 | E6: 0.81181674 | F6: 0.85913066 | H6: TransUNet Tversky | I6: =AVERAGE(D137:D150,D152:D165,D167:D180) -> 0.57800902 | J6: =_xlfn.STDEV.S(D137:D150,D152:D165,D167:D180) -> 0.27577486 | K6: =_xlfn.CONFIDENCE.T(0.05, J6, 42) -> 0.085937496 | L6: =I6-K6 -> 0.49207153 | M6: =I6+K6 -> 0.66394652 | O6: Deeplab_TVERSKY_1_Fold_2 | P6: 0.47961717 | Q6: 0.62640642 | R6: 0.62044992 | S6: 0.64361896 | U6: TransUNet Tversky | V6: =AVERAGE(P12:P14) -> 0.45125409 | W6: =AVERAGE(Q12:Q14) -> 0.57800902 | X6: =AVERAGE(R12:R14) -> 0.55671319 | Y6: =AVERAGE(S12:S14) -> 0.60846202
B7: hard_exudates | C7: 0.58270324 | D7: 0.73633923 | E7: 0.72522717 | F7: 0.7477971 | H7: SegFormer DICE | I7: =AVERAGE(D182:D195,D197:D210,D212:D225) -> 0.64869767 | J7: =_xlfn.STDEV.S(D182:D195,D197:D210,D212:D225) -> 0.17980549 | K7: =_xlfn.CONFIDENCE.T(0.05, J7, 42) -> 0.056031334 | L7: =I7-K7 -> 0.59266633 | M7: =I7+K7 -> 0.704729 | O7: Deeplab_TVERSKY_2_Fold_3 | P7: 0.50291469 | Q7: 0.64961112 | R7: 0.63982374 | S7: 0.66656019 | U7: SegFormer DICE | V7: =AVERAGE(P15:P17) -> 0.50381018 | W7: =AVERAGE(Q15:Q17) -> 0.64869767 | X7: =AVERAGE(R15:R17) -> 0.66169855 | Y7: =AVERAGE(S15:S17) -> 0.64649644
B8: hemorrhages | C8: 0.54465807 | D8: 0.70521506 | E8: 0.72748889 | F8: 0.68426464 | H8: SegFormer Tversky | I8: =AVERAGE(D227:D240,D242:D255,D257:D270) -> 0.64836229 | J8: =_xlfn.STDEV.S(D227:D240,D242:D255,D257:D270) -> 0.18161579 | K8: =_xlfn.CONFIDENCE.T(0.05, J8, 42) -> 0.056595464 | L8: =I8-K8 -> 0.59176683 | M8: =I8+K8 -> 0.70495776 | O8: Deeplab_TVERSKY_3_Fold_1 | P8: 0.48926897 | Q8: 0.62326211 | R8: 0.61914508 | S8: 0.63512391 | U8: SegFormer Tversky | V8: =AVERAGE(P18:P20) -> 0.50391065 | W8: =AVERAGE(Q18:Q20) -> 0.64836229 | X8: =AVERAGE(R18:R20) -> 0.64134021 | Y8: =AVERAGE(S18:S20) -> 0.66887029
B9: laser_coagulates | C9: 0.5413566 | D9: 0.70244173 | E9: 0.60942029 | F9: 0.82897599 | O9: TransUNet_DICE_1_Fold_1 | P9: 0.45164687 | Q9: 0.57961341 | R9: 0.56649028 | S9: 0.59881035
B10: macular_hole | C10: 0.72637375 | D10: 0.84150231 | E10: 0.74544209 | F10: 0.96598208 | O10: TransUNet_DICE_2_Fold_2 | P10: 0.41016298 | Q10: 0.53903419 | R10: 0.52553233 | S10: 0.55966784
B11: microaneurysms | C11: 0.16201701 | D11: 0.27885479 | E11: 0.31349026 | F11: 0.25111118 | H11: Recall | O11: TransUNet_DICE_3_Fold_3 | P11: 0.42202309 | Q11: 0.55197689 | R11: 0.53796543 | S11: 0.57535298
B12: neovascularization | C12: 0.58595106 | D12: 0.73892704 | E12: 0.67427259 | F12: 0.81729565 | H12: model | I12: mean | J12: std | K12: t стьюдент | L12: нижняя граница | M12: верхняя граница | O12: TransUNet_TVERSKY_1_Fold_1 | P12: 0.4639298 | Q12: 0.59131335 | R12: 0.58104836 | S12: 0.60534226 | U12: Deeplab DICE | V12: =_xlfn.STDEV.S(C2:C15,C17:C30,C32:C45) -> 0.18994851
B13: soft_exudates | C13: 0.32011139 | D13: 0.48497633 | E13: 0.7147916 | F13: 0.36698549 | H13: Deeplab DICE | I13: =AVERAGE(F2:F15,F17:F30,F32:F45) -> 0.63652624 | J13: =_xlfn.STDEV.S(F2:F15,F17:F30,F32:F45) -> 0.23877287 | K13: =_xlfn.CONFIDENCE.T(0.05, J13, 42) -> 0.074406864 | L13: =I13-K13 -> 0.56211937 | M13: =I13+K13 -> 0.7109331 | O13: TransUNet_TVERSKY_2_Fold_2 | P13: 0.43836814 | Q13: 0.56497755 | R13: 0.54798409 | S13: 0.59268194 | U13: Deeplab Tversky
B14: subretinal_hemorrhage | C14: 0.49889014 | D14: 0.66567939 | E14: 0.6453709 | F14: 0.68730755 | H14: Deeplab Tversky | I14: =AVERAGE(F47:F60,F62:F75,F77:F90) -> 0.64843435 | J14: =_xlfn.STDEV.S(F47:F60,F62:F75,F77:F90) -> 0.23244565 | K14: =_xlfn.CONFIDENCE.T(0.05, J14, 42) -> 0.072435163 | L14: =I14-K14 -> 0.57599919 | M14: =I14+K14 -> 0.72086951 | O14: TransUNet_TVERSKY_3_Fold_3 | P14: 0.45146433 | Q14: 0.57773616 | R14: 0.5411071 | S14: 0.62736186 | U14: TransUNet DICE
B15: venous_anomalies | C15: 0.12844031 | D15: 0.22764218 | E15: 0.31902241 | F15: 0.17695539 | H15: TransUNet DICE | I15: =AVERAGE(F92:F105,F107:F120,F122:F135) -> 0.57794372 | J15: =_xlfn.STDEV.S(F92:F105,F107:F120,F122:F135) -> 0.29033292 | K15: =_xlfn.CONFIDENCE.T(0.05, J15, 42) -> 0.090474106 | L15: =I15-K15 -> 0.48746962 | M15: =I15+K15 -> 0.66841783 | O15: SegFormer_DICE_1_Fold_1 | P15: 0.52338357 | Q15: 0.66815425 | R15: 0.68061532 | S15: 0.66518476 | U15: TransUNet Tversky
B16: MEAN | C16: 0.46134664 | D16: 0.60848966 | E16: 0.62419702 | F16: 0.61500231 | H16: TransUNet Tversky | I16: =AVERAGE(F137:F150,F152:F165,F167:F180) -> 0.60846202 | J16: =_xlfn.STDEV.S(F137:F150,F152:F165,F167:F180) -> 0.29720405 | K16: =_xlfn.CONFIDENCE.T(0.05, J16, 42) -> 0.092615301 | L16: =I16-K16 -> 0.51584672 | M16: =I16+K16 -> 0.70107732 | O16: SegFormer_DICE_2_Fold_2 | P16: 0.49215429 | Q16: 0.63469255 | R16: 0.63749044 | S16: 0.64447749 | U16: SegFormer DICE
A17: Deeplab_DICE_2_Fold_3 | B17: drusen | C17: 0.36219152 | D17: 0.53177768 | E17: 0.57806551 | F17: 0.49235315 | H17: SegFormer DICE | I17: =AVERAGE(F182:F195,F197:F210,F212:F225) -> 0.64649644 | J17: =_xlfn.STDEV.S(F182:F195,F197:F210,F212:F225) -> 0.21400377 | K17: =_xlfn.CONFIDENCE.T(0.05, J17, 42) -> 0.066688268 | L17: =I17-K17 -> 0.57980818 | M17: =I17+K17 -> 0.71318471 | O17: SegFormer_DICE_3_Fold_3 | P17: 0.49589269 | Q17: 0.64324621 | R17: 0.66698988 | S17: 0.62982708
B18: edema | C18: 0.30546809 | D18: 0.46798247 | E18: 0.47158011 | F18: 0.4644393 | H18: SegFormer Tversky | I18: =AVERAGE(F227:F240,F242:F255,F257:F270) -> 0.66887029 | J18: =_xlfn.STDEV.S(F227:F240,F242:F255,F257:F270) -> 0.20859518 | K18: =_xlfn.CONFIDENCE.T(0.05, J18, 42) -> 0.065002833 | L18: =I18-K18 -> 0.60386745 | M18: =I18+K18 -> 0.73387312 | O18: SegFormer_TVERSKY_1_Fold_1 | P18: 0.51929155 | Q18: 0.65864626 | R18: 0.67526206 | S18: 0.66165968
B19: epiretinal_fibrosis | C19: 0.62163749 | D19: 0.76667874 | E19: 0.70895582 | F19: 0.83463436 | O19: SegFormer_TVERSKY_2_Fold_2 | P19: 0.48945612 | Q19: 0.63448854 | R19: 0.61829314 | S19: 0.66369593
B20: fibrosis | C20: 0.3979541 | D20: 0.56933786 | E20: 0.55347016 | F20: 0.58614226 | O20: SegFormer_TVERSKY_2_Fold_3 | P20: 0.50298429 | Q20: 0.65195207 | R20: 0.63046543 | S20: 0.68125525
B21: geographic_atrophy | C21: 0.74578354 | D21: 0.8543826 | E21: 0.80398785 | F21: 0.91151741
B22: hard_exudates | C22: 0.56862376 | D22: 0.724997 | E22: 0.77104958 | F22: 0.68413555
B23: hemorrhages | C23: 0.52737846 | D23: 0.69056684 | E23: 0.692953 | F23: 0.68819705
B24: laser_coagulates | C24: 0.60125875 | D24: 0.75098262 | E24: 0.73435309 | F24: 0.76838277
B25: macular_hole | C25: 0.80415464 | D25: 0.89144758 | E25: 0.81105125 | F25: 0.98953644
B26: microaneurysms | C26: 0.13451248 | D26: 0.23712825 | E26: 0.35137892 | F26: 0.17894453
B27: neovascularization | C27: 0.57575995 | D27: 0.73077114 | E27: 0.63027987 | F27: 0.86938514
B28: soft_exudates | C28: 0.49112219 | D28: 0.65872829 | E28: 0.64140721 | F28: 0.67701085
B29: subretinal_hemorrhage | C29: 0.47939237 | D29: 0.64809361 | E29: 0.6711221 | F29: 0.62659306
B30: venous_anomalies | C30: 0.30184474 | D30: 0.4637185 | E30: 0.45995174 | F30: 0.46754746
B31: MEAN | C31: 0.49407729 | D31: 0.64189951 | E31: 0.63425759 | F31: 0.65991567
A32: Deeplab_DICE_3_Fold_1 | B32: drusen | C32: 0.36945233 | D32: 0.53956216 | E32: 0.58332884 | F32: 0.50190467
B33: edema | C33: 0.4126396 | D33: 0.58421072 | E33: 0.58173746 | F33: 0.5867051
B34: epiretinal_fibrosis | C34: 0.60407342 | D34: 0.75317427 | E34: 0.6939385 | F34: 0.82346681
B35: fibrosis | C35: 0.39101378 | D35: 0.56219972 | E35: 0.60676432 | F35: 0.52373344
B36: geographic_atrophy | C36: 0.79108313 | D36: 0.88335725 | E36: 0.82561253 | F36: 0.94978692
B37: hard_exudates | C37: 0.49878937 | D37: 0.66558968 | E37: 0.71704994 | F37: 0.6210211
B38: hemorrhages | C38: 0.58011169 | D38: 0.73426669 | E38: 0.79692391 | F38: 0.68074398
B39: laser_coagulates | C39: 0.64594001 | D39: 0.78488889 | E39: 0.72174458 | F39: 0.86014131
B40: macular_hole | C40: 0.75102697 | D40: 0.85781314 | E40: 0.76640147 | F40: 0.97398397
...

Sheet dice + recall
A1: Model | B1: Deeplab Dice | D1: Deeplab Tversky | F1: TransUNet Dice | H1: TransUNet Tversky | J1: SegFormer Dice | L1: SegFormer Tversky
A2: Metric | B2: DICE | C2: Recall | D2: DICE | E2: Recall | F2: DICE | G2: Recall | H2: DICE | I2: Recall | J2: DICE | K2: Recall | L2: DICE | M2: Recall
A3: drusen | B3: =AVERAGE('Лист1 (2)'!D2, 'Лист1 (2)'!D17,'Лист1 (2)'!D32) -> 0.52616052 | C3: =AVERAGE('Лист1 (2)'!F2, 'Лист1 (2)'!F17,'Лист1 (2)'!F32) -> 0.48063528 | D3: =AVERAGE('Лист1 (2)'!C47, 'Лист1 (2)'!D62,'Лист1 (2)'!D77) -> 0.47752318 | E3: =AVERAGE('Лист1 (2)'!F47, 'Лист1 (2)'!F62,'Лист1 (2)'!F77) -> 0.53095853 | F3: =AVERAGE('Лист1 (2)'!C92, 'Лист1 (2)'!D107,'Лист1 (2)'!D122) -> 0.28748722 | G3: =AVERAGE('Лист1 (2)'!F92, 'Лист1 (2)'!F107,'Лист1 (2)'!F122) -> 0.35213621 | H3: =AVERAGE('Лист1 (2)'!C137, 'Лист1 (2)'!D152,'Лист1 (2)'!D167) -> 0.31466766 | I3: =AVERAGE('Лист1 (2)'!F137, 'Лист1 (2)'!F152,'Лист1 (2)'!F167) -> 0.42696976 | J3: =AVERAGE('Лист1 (2)'!C182, 'Лист1 (2)'!D197,'Лист1 (2)'!D212) -> 0.49174102 | K3: =AVERAGE('Лист1 (2)'!F182, 'Лист1 (2)'!F197,'Лист1 (2)'!F212) -> 0.51531382 | L3: =AVERAGE('Лист1 (2)'!C227, 'Лист1 (2)'!D242,'Лист1 (2)'!D257) -> 0.49422301 | M3: =AVERAGE('Лист1 (2)'!F227, 'Лист1 (2)'!F242,'Лист1 (2)'!F257) -> 0.55726512
A4: edema | B4: =AVERAGE('Лист1 (2)'!D3, 'Лист1 (2)'!D18,'Лист1 (2)'!D33) -> 0.5305412 | C4: =AVERAGE('Лист1 (2)'!F3, 'Лист1 (2)'!F18,'Лист1 (2)'!F33) -> 0.52857797 | D4: =AVERAGE('Лист1 (2)'!C48, 'Лист1 (2)'!D63,'Лист1 (2)'!D78) -> 0.4722652 | E4: =AVERAGE('Лист1 (2)'!F48, 'Лист1 (2)'!F63,'Лист1 (2)'!F78) -> 0.49232876 | F4: =AVERAGE('Лист1 (2)'!C93, 'Лист1 (2)'!D108,'Лист1 (2)'!D123) -> 0.45467162 | G4: =AVERAGE('Лист1 (2)'!F93, 'Лист1 (2)'!F108,'Лист1 (2)'!F123) -> 0.4718224 | H4: =AVERAGE('Лист1 (2)'!C138, 'Лист1 (2)'!D153,'Лист1 (2)'!D168) -> 0.4807988 | I4: =AVERAGE('Лист1 (2)'!F138, 'Лист1 (2)'!F153,'Лист1 (2)'!F168) -> 0.49841923 | J4: =AVERAGE('Лист1 (2)'!C183, 'Лист1 (2)'!D198,'Лист1 (2)'!D213) -> 0.45628727 | K4: =AVERAGE('Лист1 (2)'!F183, 'Лист1 (2)'!F198,'Лист1 (2)'!F213) -> 0.48722997 | L4: =AVERAGE('Лист1 (2)'!C228, 'Лист1 (2)'!D243,'Лист1 (2)'!D258) -> 0.4662315 | M4: =AVERAGE('Лист1 (2)'!F228, 'Лист1 (2)'!F243,'Лист1 (2)'!F258) -> 0.51097216
A5: epiretinal_fibrosis | B5: =AVERAGE('Лист1 (2)'!D4, 'Лист1 (2)'!D19,'Лист1 (2)'!D34) -> 0.76015721 | C5: =AVERAGE('Лист1 (2)'!F4, 'Лист1 (2)'!F19,'Лист1 (2)'!F34) -> 0.82946331 | D5: =AVERAGE('Лист1 (2)'!C49, 'Лист1 (2)'!D64,'Лист1 (2)'!D79) -> 0.72494395 | E5: =AVERAGE('Лист1 (2)'!F49, 'Лист1 (2)'!F64,'Лист1 (2)'!F79) -> 0.81882108 | F5: =AVERAGE('Лист1 (2)'!C94, 'Лист1 (2)'!D109,'Лист1 (2)'!D124) -> 0.70281988 | G5: =AVERAGE('Лист1 (2)'!F94, 'Лист1 (2)'!F109,'Лист1 (2)'!F124) -> 0.73376536 | H5: =AVERAGE('Лист1 (2)'!C139, 'Лист1 (2)'!D154,'Лист1 (2)'!D169) -> 0.74168001 | I5: =AVERAGE('Лист1 (2)'!F139, 'Лист1 (2)'!F154,'Лист1 (2)'!F169) -> 0.81884348 | J5: =AVERAGE('Лист1 (2)'!C184, 'Лист1 (2)'!D199,'Лист1 (2)'!D214) -> 0.71926731 | K5: =AVERAGE('Лист1 (2)'!F184, 'Лист1 (2)'!F199,'Лист1 (2)'!F214) -> 0.78537489 | L5: =AVERAGE('Лист1 (2)'!C229, 'Лист1 (2)'!D244,'Лист1 (2)'!D259) -> 0.7192442 | M5: =AVERAGE('Лист1 (2)'!F229, 'Лист1 (2)'!F244,'Лист1 (2)'!F259) -> 0.80824648
A6: fibrosis | B6: =AVERAGE('Лист1 (2)'!D5, 'Лист1 (2)'!D20,'Лист1 (2)'!D35) -> 0.54227341 | C6: =AVERAGE('Лист1 (2)'!F5, 'Лист1 (2)'!F20,'Лист1 (2)'!F35) -> 0.50719204 | D6: =AVERAGE('Лист1 (2)'!C50, 'Лист1 (2)'!D65,'Лист1 (2)'!D80) -> 0.51386906 | E6: =AVERAGE('Лист1 (2)'!F50, 'Лист1 (2)'!F65,'Лист1 (2)'!F80) -> 0.55491217 | F6: =AVERAGE('Лист1 (2)'!C95, 'Лист1 (2)'!D110,'Лист1 (2)'!D125) -> 0.49388153 | G6: =AVERAGE('Лист1 (2)'!F95, 'Лист1 (2)'!F110,'Лист1 (2)'!F125) -> 0.54046026 | H6: =AVERAGE('Лист1 (2)'!C140, 'Лист1 (2)'!D155,'Лист1 (2)'!D170) -> 0.51288764 | I6: =AVERAGE('Лист1 (2)'!F140, 'Лист1 (2)'!F155,'Лист1 (2)'!F170) -> 0.58941182 | J6: =AVERAGE('Лист1 (2)'!C185, 'Лист1 (2)'!D200,'Лист1 (2)'!D215) -> 0.53224795 | K6: =AVERAGE('Лист1 (2)'!F185, 'Лист1 (2)'!F200,'Лист1 (2)'!F215) -> 0.54122435 | L6: =AVERAGE('Лист1 (2)'!C230, 'Лист1 (2)'!D245,'Лист1 (2)'!D260) -> 0.52792503 | M6: =AVERAGE('Лист1 (2)'!F230, 'Лист1 (2)'!F245,'Лист1 (2)'!F260) -> 0.54922932
A7: geographic_atrophy | B7: =AVERAGE('Лист1 (2)'!D6, 'Лист1 (2)'!D21,'Лист1 (2)'!D36) -> 0.85751456 | C7: =AVERAGE('Лист1 (2)'!F6, 'Лист1 (2)'!F21,'Лист1 (2)'!F36) -> 0.90681167 | D7: =AVERAGE('Лист1 (2)'!C51, 'Лист1 (2)'!D66,'Лист1 (2)'!D81) -> 0.82307759 | E7: =AVERAGE('Лист1 (2)'!F51, 'Лист1 (2)'!F66,'Лист1 (2)'!F81) -> 0.91215983 | F7: =AVERAGE('Лист1 (2)'!C96, 'Лист1 (2)'!D111,'Лист1 (2)'!D126) -> 0.83531392 | G7: =AVERAGE('Лист1 (2)'!F96, 'Лист1 (2)'!F111,'Лист1 (2)'!F126) -> 0.87605144 | H7: =AVERAGE('Лист1 (2)'!C141, 'Лист1 (2)'!D156,'Лист1 (2)'!D171) -> 0.84497476 | I7: =AVERAGE('Лист1 (2)'!F141, 'Лист1 (2)'!F156,'Лист1 (2)'!F171) -> 0.90967003 | J7: =AVERAGE('Лист1 (2)'!C186, 'Лист1 (2)'!D201,'Лист1 (2)'!D216) -> 0.82784348 | K7: =AVERAGE('Лист1 (2)'!F186, 'Лист1 (2)'!F201,'Лист1 (2)'!F216) -> 0.89445334 | L7: =AVERAGE('Лист1 (2)'!C231, 'Лист1 (2)'!D246,'Лист1 (2)'!D261) -> 0.83596962 | M7: =AVERAGE('Лист1 (2)'!F231, 'Лист1 (2)'!F246,'Лист1 (2)'!F261) -> 0.91918521
A8: hard_exudates | B8: =AVERAGE('Лист1 (2)'!D7, 'Лист1 (2)'!D22,'Лист1 (2)'!D37) -> 0.7089753 | C8: =AVERAGE('Лист1 (2)'!F7, 'Лист1 (2)'!F22,'Лист1 (2)'!F37) -> 0.68431792 | D8: =AVERAGE('Лист1 (2)'!C52, 'Лист1 (2)'!D67,'Лист1 (2)'!D82) -> 0.65297779 | E8: =AVERAGE('Лист1 (2)'!F52, 'Лист1 (2)'!F67,'Лист1 (2)'!F82) -> 0.68144279 | F8: =AVERAGE('Лист1 (2)'!C97, 'Лист1 (2)'!D112,'Лист1 (2)'!D127) -> 0.55179411 | G8: =AVERAGE('Лист1 (2)'!F97, 'Лист1 (2)'!F112,'Лист1 (2)'!F127) -> 0.6157642 | H8: =AVERAGE('Лист1 (2)'!C142, 'Лист1 (2)'!D157,'Лист1 (2)'!D172) -> 0.55704274 | I8: =AVERAGE('Лист1 (2)'!F142, 'Лист1 (2)'!F157,'Лист1 (2)'!F172) -> 0.66838561 | J8: =AVERAGE('Лист1 (2)'!C187, 'Лист1 (2)'!D202,'Лист1 (2)'!D217) -> 0.67524683 | K8: =AVERAGE('Лист1 (2)'!F187, 'Лист1 (2)'!F202,'Лист1 (2)'!F217) -> 0.70912735 | L8: =AVERAGE('Лист1 (2)'!C232, 'Лист1 (2)'!D247,'Лист1 (2)'!D262) -> 0.66728536 | M8: =AVERAGE('Лист1 (2)'!F232, 'Лист1 (2)'!F247,'Лист1 (2)'!F262) -> 0.73091418
A9: hemorrhages | B9: =AVERAGE('Лист1 (2)'!D8, 'Лист1 (2)'!D23,'Лист1 (2)'!D38) -> 0.7100162 | C9: =AVERAGE('Лист1 (2)'!F8, 'Лист1 (2)'!F23,'Лист1 (2)'!F38) -> 0.68440189 | D9: =AVERAGE('Лист1 (2)'!C53, 'Лист1 (2)'!D68,'Лист1 (2)'!D83) -> 0.65363904 | E9: =AVERAGE('Лист1 (2)'!F53, 'Лист1 (2)'!F68,'Лист1 (2)'!F83) -> 0.69710729 | F9: =AVERAGE('Лист1 (2)'!C98, 'Лист1 (2)'!D113,'Лист1 (2)'!D128) -> 0.66248851 | G9: =AVERAGE('Лист1 (2)'!F98, 'Лист1 (2)'!F113,'Лист1 (2)'!F128) -> 0.71637217 | H9: =AVERAGE('Лист1 (2)'!C143, 'Лист1 (2)'!D158,'Лист1 (2)'!D173) -> 0.65098655 | I9: =AVERAGE('Лист1 (2)'!F143, 'Лист1 (2)'!F158,'Лист1 (2)'!F173) -> 0.71331212 | J9: =AVERAGE('Лист1 (2)'!C188, 'Лист1 (2)'!D203,'Лист1 (2)'!D218) -> 0.67746204 | K9: =AVERAGE('Лист1 (2)'!F188, 'Лист1 (2)'!F203,'Лист1 (2)'!F218) -> 0.72306692 | L9: =AVERAGE('Лист1 (2)'!C233, 'Лист1 (2)'!D248,'Лист1 (2)'!D263) -> 0.68543245 | M9: =AVERAGE('Лист1 (2)'!F233, 'Лист1 (2)'!F248,'Лист1 (2)'!F263) -> 0.73463558
A10: laser_coagulates | B10: =AVERAGE('Лист1 (2)'!D9, 'Лист1 (2)'!D24,'Лист1 (2)'!D39) -> 0.74610442 | C10: =AVERAGE('Лист1 (2)'!F9, 'Лист1 (2)'!F24,'Лист1 (2)'!F39) -> 0.81916669 | D10: =AVERAGE('Лист1 (2)'!C54, 'Лист1 (2)'!D69,'Лист1 (2)'!D84) -> 0.69164122 | E10: =AVERAGE('Лист1 (2)'!F54, 'Лист1 (2)'!F69,'Лист1 (2)'!F84) -> 0.84363614 | F10: =AVERAGE('Лист1 (2)'!C99, 'Лист1 (2)'!D114,'Лист1 (2)'!D129) -> 0.65969566 | G10: =AVERAGE('Лист1 (2)'!F99, 'Лист1 (2)'!F114,'Лист1 (2)'!F129) -> 0.81434933 | H10: =AVERAGE('Лист1 (2)'!C144, 'Лист1 (2)'!D159,'Лист1 (2)'!D174) -> 0.7142223 | I10: =AVERAGE('Лист1 (2)'!F144, 'Лист1 (2)'!F159,'Лист1 (2)'!F174) -> 0.85568776 | J10: =AVERAGE('Лист1 (2)'!C189, 'Лист1 (2)'!D204,'Лист1 (2)'!D219) -> 0.72694549 | K10: =AVERAGE('Лист1 (2)'!F189, 'Лист1 (2)'!F204,'Лист1 (2)'!F219) -> 0.86368558 | L10: =AVERAGE('Лист1 (2)'!C234, 'Лист1 (2)'!D249,'Лист1 (2)'!D264) -> 0.72817515 | M10: =AVERAGE('Лист1 (2)'!F234, 'Лист1 (2)'!F249,'Лист1 (2)'!F264) -> 0.88515459
A11: macular_hole | B11: =AVERAGE('Лист1 (2)'!D10, 'Лист1 (2)'!D25,'Лист1 (2)'!D40) -> 0.86358768 | C11: =AVERAGE('Лист1 (2)'!F10, 'Лист1 (2)'!F25,'Лист1 (2)'!F40) -> 0.97650083 | D11: =AVERAGE('Лист1 (2)'!C55, 'Лист1 (2)'!D70,'Лист1 (2)'!D85) -> 0.848133 | E11: =AVERAGE('Лист1 (2)'!F55, 'Лист1 (2)'!F70,'Лист1 (2)'!F85) -> 0.97761278 | F11: =AVERAGE('Лист1 (2)'!C100, 'Лист1 (2)'!D115,'Лист1 (2)'!D130) -> 0.80640018 | G11: =AVERAGE('Лист1 (2)'!F100, 'Лист1 (2)'!F115,'Лист1 (2)'!F130) -> 0.95440885 | H11: =AVERAGE('Лист1 (2)'!C145, 'Лист1 (2)'!D160,'Лист1 (2)'!D175) -> 0.8146249 | I11: =AVERAGE('Лист1 (2)'!F145, 'Лист1 (2)'!F160,'Лист1 (2)'!F175) -> 0.95319579 | J11: =AVERAGE('Лист1 (2)'!C190, 'Лист1 (2)'!D205,'Лист1 (2)'!D220) -> 0.85349223 | K11: =AVERAGE('Лист1 (2)'!F190, 'Лист1 (2)'!F205,'Лист1 (2)'!F220) -> 0.96000553 | L11: =AVERAGE('Лист1 (2)'!C235, 'Лист1 (2)'!D250,'Лист1 (2)'!D265) -> 0.8640724 | M11: =AVERAGE('Лист1 (2)'!F235, 'Лист1 (2)'!F250,'Лист1 (2)'!F265) -> 0.96392541
A12: microaneurysms | B12: =AVERAGE('Лист1 (2)'!D11, 'Лист1 (2)'!D26,'Лист1 (2)'!D41) -> 0.26074087 | C12: =AVERAGE('Лист1 (2)'!F11, 'Лист1 (2)'!F26,'Лист1 (2)'!F41) -> 0.21598127 | D12: =AVERAGE('Лист1 (2)'!C56, 'Лист1 (2)'!D71,'Лист1 (2)'!D86) -> 0.18897702 | E12: =AVERAGE('Лист1 (2)'!F56, 'Лист1 (2)'!F71,'Лист1 (2)'!F86) -> 0.20638546 | F12: =AVERAGE('Лист1 (2)'!C101, 'Лист1 (2)'!D116,'Лист1 (2)'!D131) -> 0 | G12: =AVERAGE('Лист1 (2)'!F101, 'Лист1 (2)'!F116,'Лист1 (2)'!F131) -> 0 | H12: =AVERAGE('Лист1 (2)'!C146, 'Лист1 (2)'!D161,'Лист1 (2)'!D176) -> 0 | I12: =AVERAGE('Лист1 (2)'!F146, 'Лист1 (2)'!F161,'Лист1 (2)'!F176) -> 0 | J12: =AVERAGE('Лист1 (2)'!C191, 'Лист1 (2)'!D206,'Лист1 (2)'!D221) -> 0.31106768 | K12: =AVERAGE('Лист1 (2)'!F191, 'Лист1 (2)'!F206,'Лист1 (2)'!F221) -> 0.35026918 | L12: =AVERAGE('Лист1 (2)'!C236, 'Лист1 (2)'!D251,'Лист1 (2)'!D266) -> 0.31315629 | M12: =AVERAGE('Лист1 (2)'!F236, 'Лист1 (2)'!F251,'Лист1 (2)'!F266) -> 0.43463885
A13: neovascularization | B13: =AVERAGE('Лист1 (2)'!D12, 'Лист1 (2)'!D27,'Лист1 (2)'!D42) -> 0.73876589 | C13: =AVERAGE('Лист1 (2)'!F12, 'Лист1 (2)'!F27,'Лист1 (2)'!F42) -> 0.82710049 | D13: =AVERAGE('Лист1 (2)'!C57, 'Лист1 (2)'!D72,'Лист1 (2)'!D87) -> 0.71210966 | E13: =AVERAGE('Лист1 (2)'!F57, 'Лист1 (2)'!F72,'Лист1 (2)'!F87) -> 0.83382581 | F13: =AVERAGE('Лист1 (2)'!C102, 'Лист1 (2)'!D117,'Лист1 (2)'!D132) -> 0.66364959 | G13: =AVERAGE('Лист1 (2)'!F102, 'Лист1 (2)'!F117,'Лист1 (2)'!F132) -> 0.76186673 | H13: =AVERAGE('Лист1 (2)'!C147, 'Лист1 (2)'!D162,'Лист1 (2)'!D177) -> 0.6917664 | I13: =AVERAGE('Лист1 (2)'!F147, 'Лист1 (2)'!F162,'Лист1 (2)'!F177) -> 0.78532638 | J13: =AVERAGE('Лист1 (2)'!C192, 'Лист1 (2)'!D207,'Лист1 (2)'!D222) -> 0.68802751 | K13: =AVERAGE('Лист1 (2)'!F192, 'Лист1 (2)'!F207,'Лист1 (2)'!F222) -> 0.75888186 | L13: =AVERAGE('Лист1 (2)'!C237, 'Лист1 (2)'!D252,'Лист1 (2)'!D267) -> 0.69279966 | M13: =AVERAGE('Лист1 (2)'!F237, 'Лист1 (2)'!F252,'Лист1 (2)'!F267) -> 0.77659053
A14: soft_exudates | B14: =AVERAGE('Лист1 (2)'!D13, 'Лист1 (2)'!D28,'Лист1 (2)'!D43) -> 0.60848585 | C14: =AVERAGE('Лист1 (2)'!F13, 'Лист1 (2)'!F28,'Лист1 (2)'!F43) -> 0.5410528 | D14: =AVERAGE('Лист1 (2)'!C58, 'Лист1 (2)'!D73,'Лист1 (2)'!D88) -> 0.56739532 | E14: =AVERAGE('Лист1 (2)'!F58, 'Лист1 (2)'!F73,'Лист1 (2)'!F88) -> 0.57448119 | F14: =AVERAGE('Лист1 (2)'!C103, 'Лист1 (2)'!D118,'Лист1 (2)'!D133) -> 0.45090818 | G14: =AVERAGE('Лист1 (2)'!F103, 'Лист1 (2)'!F118,'Лист1 (2)'!F133) -> 0.52366951 | H14: =AVERAGE('Лист1 (2)'!C148, 'Лист1 (2)'!D163,'Лист1 (2)'!D178) -> 0.50412142 | I14: =AVERAGE('Лист1 (2)'!F148, 'Лист1 (2)'!F163,'Лист1 (2)'!F178) -> 0.55642187 | J14: =AVERAGE('Лист1 (2)'!C193, 'Лист1 (2)'!D208,'Лист1 (2)'!D223) -> 0.57678043 | K14: =AVERAGE('Лист1 (2)'!F193, 'Лист1 (2)'!F208,'Лист1 (2)'!F223) -> 0.58202012 | L14: =AVERAGE('Лист1 (2)'!C238, 'Лист1 (2)'!D253,'Лист1 (2)'!D268) -> 0.56558376 | M14: =AVERAGE('Лист1 (2)'!F238, 'Лист1 (2)'!F253,'Лист1 (2)'!F268) -> 0.61003917
... A16: venous_anomalies | B16: =AVERAGE('Лист1 (2)'!D15, 'Лист1 (2)'!D30,'Лист1 (2)'!D45) -> 0.24861867 | C16: =AVERAGE('Лист1 (2)'!F15, 'Лист1 (2)'!F30,'Лист1 (2)'!F45) -> 0.22431545 | D16: =AVERAGE('Лист1 (2)'!C60, 'Лист1 (2)'!D75,'Лист1 (2)'!D90) -> 0.23724868 | E16: =AVERAGE('Лист1 (2)'!F60, 'Лист1 (2)'!F75,'Лист1 (2)'!F90) -> 0.28518951 | F16: =AVERAGE('Лист1 (2)'!C105, 'Лист1 (2)'!D120,'Лист1 (2)'!D135) -> 0 | G16: =AVERAGE('Лист1 (2)'!F105, 'Лист1 (2)'!F120,'Лист1 (2)'!F135) -> 0 | H16: =AVERAGE('Лист1 (2)'!C150, 'Лист1 (2)'!D165,'Лист1 (2)'!D180) -> 0 | I16: =AVERAGE('Лист1 (2)'!F150, 'Лист1 (2)'!F165,'Лист1 (2)'!F180) -> 0 | J16: =AVERAGE('Лист1 (2)'!C195, 'Лист1 (2)'!D210,'Лист1 (2)'!D225) -> 0.22573043 | K16: =AVERAGE('Лист1 (2)'!F195, 'Лист1 (2)'!F210,'Лист1 (2)'!F225) -> 0.21209556 | L16: =AVERAGE('Лист1 (2)'!C240, 'Лист1 (2)'!D255,'Лист1 (2)'!D270) -> 0.23869689 | M16: =AVERAGE('Лист1 (2)'!F240, 'Лист1 (2)'!F255,'Лист1 (2)'!F270) -> 0.2180516
A17: Mean | B17: =AVERAGE(B3:B16) -> 0.62677504 | C17: =AVERAGE(C3:C16) -> 0.63652624 | D17: =AVERAGE(D3:D16) -> 0.58416347 | E17: =AVERAGE(E3:E16) -> 0.64843435 | F17: =AVERAGE(F3:F16) -> 0.51421932 | G17: =AVERAGE(G3:G16) -> 0.57794372 | H17: =AVERAGE(H3:H16) -> 0.53554784 | I17: =AVERAGE(I3:I16) -> 0.60846202 | ... M17: =AVERAGE(M3:M16) -> 0.66887029
B21: std
A22: Model | B22: Deeplab Dice | D22: Deeplab Tversky | F22: TransUNet Dice | H22: TransUNet Tversky | J22: SegFormer Dice | L22: SegFormer Tversky
A23: Metric | B23: DICE | C23: Recall | D23: DICE | E23: Recall | F23: DICE | G23: Recall | H23: DICE | I23: Recall | J23: DICE | K23: Recall | L23: DICE | M23: Recall
A24: drusen | B24: =_xlfn.STDEV.S('Лист1 (2)'!D2, 'Лист1 (2)'!D17,'Лист1 (2)'!D32) -> 0.016924419 | C24: =_xlfn.STDEV.S('Лист1 (2)'!F2, 'Лист1 (2)'!F17,'Лист1 (2)'!F32) -> 0.028964254 | D24: =_xlfn.STDEV.S('Лист1 (2)'!C47, 'Лист1 (2)'!D62,'Лист1 (2)'!D77) -> 0.11705736 | E24: =_xlfn.STDEV.S('Лист1 (2)'!F47, 'Лист1 (2)'!F62,'Лист1 (2)'!F77) -> 0.028061803 | F24: =_xlfn.STDEV.S('Лист1 (2)'!C92, 'Лист1 (2)'!D107,'Лист1 (2)'!D122) -> 0.048040274 | G24: =_xlfn.STDEV.S('Лист1 (2)'!F92, 'Лист1 (2)'!F107,'Лист1 (2)'!F122) -> 0.061306382 | H24: =_xlfn.STDEV.S('Лист1 (2)'!C137, 'Лист1 (2)'!D152,'Лист1 (2)'!D167) -> 0.056379473 | I24: =_xlfn.STDEV.S('Лист1 (2)'!F137, 'Лист1 (2)'!F152,'Лист1 (2)'!F167) -> 0.068357043 | J24: =_xlfn.STDEV.S('Лист1 (2)'!C182, 'Лист1 (2)'!D197,'Лист1 (2)'!D212) -> 0.081130311 | K24: =_xlfn.STDEV.S('Лист1 (2)'!F182, 'Лист1 (2)'!F197,'Лист1 (2)'!F212) -> 0.022336762 | L24: =_xlfn.STDEV.S('Лист1 (2)'!C227, 'Лист1 (2)'!D242,'Лист1 (2)'!D257) -> 0.08220345 | M24: =_xlfn.STDEV.S('Лист1 (2)'!F227, 'Лист1 (2)'!F242,'Лист1 (2)'!F257) -> 0.035810175
A25: edema | B25: =_xlfn.STDEV.S('Лист1 (2)'!D3, 'Лист1 (2)'!D18,'Лист1 (2)'!D33) -> 0.0586218 | C25: =_xlfn.STDEV.S('Лист1 (2)'!F3, 'Лист1 (2)'!F18,'Лист1 (2)'!F33) -> 0.061354182 | D25: =_xlfn.STDEV.S('Лист1 (2)'!C48, 'Лист1 (2)'!D63,'Лист1 (2)'!D78) -> 0.10562992 | E25: =_xlfn.STDEV.S('Лист1 (2)'!F48, 'Лист1 (2)'!F63,'Лист1 (2)'!F78) -> 0.097460682 | F25: =_xlfn.STDEV.S('Лист1 (2)'!C93, 'Лист1 (2)'!D108,'Лист1 (2)'!D123) -> 0.046756809 | G25: =_xlfn.STDEV.S('Лист1 (2)'!F93, 'Лист1 (2)'!F108,'Лист1 (2)'!F123) -> 0.086894137 | H25: =_xlfn.STDEV.S('Лист1 (2)'!C138, 'Лист1 (2)'!D153,'Лист1 (2)'!D168) -> 0.084845371 | I25: =_xlfn.STDEV.S('Лист1 (2)'!F138, 'Лист1 (2)'!F153,'Лист1 (2)'!F168) -> 0.098488853 | J25: =_xlfn.STDEV.S('Лист1 (2)'!C183, 'Лист1 (2)'!D198,'Лист1 (2)'!D213) -> 0.11523657 | K25: =_xlfn.STDEV.S('Лист1 (2)'!F183, 'Лист1 (2)'!F198,'Лист1 (2)'!F213) -> 0.10529808 | L25: =_xlfn.STDEV.S('Лист1 (2)'!C228, 'Лист1 (2)'!D243,'Лист1 (2)'!D258) -> 0.094468314 | M25: =_xlfn.STDEV.S('Лист1 (2)'!F228, 'Лист1 (2)'!F243,'Лист1 (2)'!F258) -> 0.092316672
A26: epiretinal_fibrosis | B26: =_xlfn.STDEV.S('Лист1 (2)'!D4, 'Лист1 (2)'!D19,'Лист1 (2)'!D34) -> 0.0067640452 | C26: =_xlfn.STDEV.S('Лист1 (2)'!F4, 'Лист1 (2)'!F19,'Лист1 (2)'!F34) -> 0.0056293498 | D26: =_xlfn.STDEV.S('Лист1 (2)'!C49, 'Лист1 (2)'!D64,'Лист1 (2)'!D79) -> 0.072853691 | E26: =_xlfn.STDEV.S('Лист1 (2)'!F49, 'Лист1 (2)'!F64,'Лист1 (2)'!F79) -> 0.023187261 | F26: =_xlfn.STDEV.S('Лист1 (2)'!C94, 'Лист1 (2)'!D109,'Лист1 (2)'!D124) -> 0.09706132 | G26: =_xlfn.STDEV.S('Лист1 (2)'!F94, 'Лист1 (2)'!F109,'Лист1 (2)'!F124) -> 0.023991145 | H26: =_xlfn.STDEV.S('Лист1 (2)'!C139, 'Лист1 (2)'!D154,'Лист1 (2)'!D169) -> 0.095332509 | I26: =_xlfn.STDEV.S('Лист1 (2)'!F139, 'Лист1 (2)'!F154,'Лист1 (2)'!F169) -> 0.030903626 | J26: =_xlfn.STDEV.S('Лист1 (2)'!C184, 'Лист1 (2)'!D199,'Лист1 (2)'!D214) -> 0.048072182 | K26: =_xlfn.STDEV.S('Лист1 (2)'!F184, 'Лист1 (2)'!F199,'Лист1 (2)'!F214) -> 0.055984342 | L26: =_xlfn.STDEV.S('Лист1 (2)'!C229, 'Лист1 (2)'!D244,'Лист1 (2)'!D259) -> 0.060751777 | M26: =_xlfn.STDEV.S('Лист1 (2)'!F229, 'Лист1 (2)'!F244,'Лист1 (2)'!F259) -> 0.049881084
A27: fibrosis | B27: =_xlfn.STDEV.S('Лист1 (2)'!D5, 'Лист1 (2)'!D20,'Лист1 (2)'!D35) -> 0.0408514 | C27: =_xlfn.STDEV.S('Лист1 (2)'!F5, 'Лист1 (2)'!F20,'Лист1 (2)'!F35) -> 0.088389499 | D27: =_xlfn.STDEV.S('Лист1 (2)'!C50, 'Лист1 (2)'!D65,'Лист1 (2)'!D80) -> 0.1375104 | E27: =_xlfn.STDEV.S('Лист1 (2)'!F50, 'Лист1 (2)'!F65,'Лист1 (2)'!F80) -> 0.073793354 | F27: =_xlfn.STDEV.S('Лист1 (2)'!C95, 'Лист1 (2)'!D110,'Лист1 (2)'!D125) -> 0.063777146 | G27: =_xlfn.STDEV.S('Лист1 (2)'!F95, 'Лист1 (2)'!F110,'Лист1 (2)'!F125) -> 0.042133215 | H27: =_xlfn.STDEV.S('Лист1 (2)'!C140, 'Лист1 (2)'!D155,'Лист1 (2)'!D170) -> 0.078918077 | I27: =_xlfn.STDEV.S('Лист1 (2)'!F140, 'Лист1 (2)'!F155,'Лист1 (2)'!F170) -> 0.058121428 | J27: =_xlfn.STDEV.S('Лист1 (2)'!C185, 'Лист1 (2)'!D200,'Лист1 (2)'!D215) -> 0.071694547 | K27: =_xlfn.STDEV.S('Лист1 (2)'!F185, 'Лист1 (2)'!F200,'Лист1 (2)'!F215) -> 0.037942569 | L27: =_xlfn.STDEV.S('Лист1 (2)'!C230, 'Лист1 (2)'!D245,'Лист1 (2)'!D260) -> 0.078270201 | M27: =_xlfn.STDEV.S('Лист1 (2)'!F230, 'Лист1 (2)'!F245,'Лист1 (2)'!F260) -> 0.038928132
A28: geographic_atrophy | B28: =_xlfn.STDEV.S('Лист1 (2)'!D6, 'Лист1 (2)'!D21,'Лист1 (2)'!D36) -> 0.024427758 | C28: =_xlfn.STDEV.S('Лист1 (2)'!F6, 'Лист1 (2)'!F21,'Лист1 (2)'!F36) -> 0.045510963 | D28: =_xlfn.STDEV.S('Лист1 (2)'!C51, 'Лист1 (2)'!D66,'Лист1 (2)'!D81) -> 0.082493733 | E28: =_xlfn.STDEV.S('Лист1 (2)'!F51, 'Лист1 (2)'!F66,'Лист1 (2)'!F81) -> 0.045689084 | F28: =_xlfn.STDEV.S('Лист1 (2)'!C96, 'Лист1 (2)'!D111,'Лист1 (2)'!D126) -> 0.010220599 | G28: =_xlfn.STDEV.S('Лист1 (2)'!F96, 'Лист1 (2)'!F111,'Лист1 (2)'!F126) -> 0.052646393 | H28: =_xlfn.STDEV.S('Лист1 (2)'!C141, 'Лист1 (2)'!D156,'Лист1 (2)'!D171) -> 0.029134835 | I28: =_xlfn.STDEV.S('Лист1 (2)'!F141, 'Лист1 (2)'!F156,'Лист1 (2)'!F171) -> 0.034629827 | J28: =_xlfn.STDEV.S('Лист1 (2)'!C186, 'Лист1 (2)'!D201,'Лист1 (2)'!D216) -> 0.032714647 | K28: =_xlfn.STDEV.S('Лист1 (2)'!F186, 'Лист1 (2)'!F201,'Лист1 (2)'!F216) -> 0.04639126 | L28: =_xlfn.STDEV.S('Лист1 (2)'!C231, 'Лист1 (2)'!D246,'Лист1 (2)'!D261) -> 0.019021693 | M28: =_xlfn.STDEV.S('Лист1 (2)'!F231, 'Лист1 (2)'!F246,'Лист1 (2)'!F261) -> 0.024485433
A29: hard_exudates | B29: =_xlfn.STDEV.S('Лист1 (2)'!D7, 'Лист1 (2)'!D22,'Лист1 (2)'!D37) -> 0.037998625 | C29: =_xlfn.STDEV.S('Лист1 (2)'!F7, 'Лист1 (2)'!F22,'Лист1 (2)'!F37) -> 0.063388199 | D29: =_xlfn.STDEV.S('Лист1 (2)'!C52, 'Лист1 (2)'!D67,'Лист1 (2)'!D82) -> 0.07432246 | E29: =_xlfn.STDEV.S('Лист1 (2)'!F52, 'Лист1 (2)'!F67,'Лист1 (2)'!F82) -> 0.061125529 | F29: =_xlfn.STDEV.S('Лист1 (2)'!C97, 'Лист1 (2)'!D112,'Лист1 (2)'!D127) -> 0.13204755 | G29: =_xlfn.STDEV.S('Лист1 (2)'!F97, 'Лист1 (2)'!F112,'Лист1 (2)'!F127) -> 0.030614099 | H29: =_xlfn.STDEV.S('Лист1 (2)'!C142, 'Лист1 (2)'!D157,'Лист1 (2)'!D172) -> 0.12940257 | I29: =_xlfn.STDEV.S('Лист1 (2)'!F142, 'Лист1 (2)'!F157,'Лист1 (2)'!F172) -> 0.05896571 | J29: =_xlfn.STDEV.S('Лист1 (2)'!C187, 'Лист1 (2)'!D202,'Лист1 (2)'!D217) -> 0.13758253 | K29: =_xlfn.STDEV.S('Лист1 (2)'!F187, 'Лист1 (2)'!F202,'Лист1 (2)'!F217) -> 0.044904513 | L29: =_xlfn.STDEV.S('Лист1 (2)'!C232, 'Лист1 (2)'!D247,'Лист1 (2)'!D262) -> 0.12261553 | M29: =_xlfn.STDEV.S('Лист1 (2)'!F232, 'Лист1 (2)'!F247,'Лист1 (2)'!F262) -> 0.026116417
A30: hemorrhages | B30: =_xlfn.STDEV.S('Лист1 (2)'!D8, 'Лист1 (2)'!D23,'Лист1 (2)'!D38) -> 0.022242018 | C30: =_xlfn.STDEV.S('Лист1 (2)'!F8, 'Лист1 (2)'!F23,'Лист1 (2)'!F38) -> 0.0037284307 | D30: =_xlfn.STDEV.S('Лист1 (2)'!C53, 'Лист1 (2)'!D68,'Лист1 (2)'!D83) -> 0.10125354 | E30: =_xlfn.STDEV.S('Лист1 (2)'!F53, 'Лист1 (2)'!F68,'Лист1 (2)'!F83) -> 0.0064019183 | F30: =_xlfn.STDEV.S('Лист1 (2)'!C98, 'Лист1 (2)'!D113,'Лист1 (2)'!D128) -> 0.058866189 | G30: =_xlfn.STDEV.S('Лист1 (2)'!F98, 'Лист1 (2)'!F113,'Лист1 (2)'!F128) -> 0.046831352 | H30: =_xlfn.STDEV.S('Лист1 (2)'!C143, 'Лист1 (2)'!D158,'Лист1 (2)'!D173) -> 0.088763019 | I30: =_xlfn.STDEV.S('Лист1 (2)'!F143, 'Лист1 (2)'!F158,'Лист1 (2)'!F173) -> 0.045415005 | J30: =_xlfn.STDEV.S('Лист1 (2)'!C188, 'Лист1 (2)'!D203,'Лист1 (2)'!D218) -> 0.095930986 | K30: =_xlfn.STDEV.S('Лист1 (2)'!F188, 'Лист1 (2)'!F203,'Лист1 (2)'!F218) -> 0.050831817 | L30: =_xlfn.STDEV.S('Лист1 (2)'!C233, 'Лист1 (2)'!D248,'Лист1 (2)'!D263) -> 0.091475724 | M30: =_xlfn.STDEV.S('Лист1 (2)'!F233, 'Лист1 (2)'!F248,'Лист1 (2)'!F263) -> 0.035879758
A31: laser_coagulates | B31: =_xlfn.STDEV.S('Лист1 (2)'!D9, 'Лист1 (2)'!D24,'Лист1 (2)'!D39) -> 0.041439487 | C31: =_xlfn.STDEV.S('Лист1 (2)'!F9, 'Лист1 (2)'!F24,'Лист1 (2)'!F39) -> 0.046659129 | D31: =_xlfn.STDEV.S('Лист1 (2)'!C54, 'Лист1 (2)'!D69,'Лист1 (2)'!D84) -> 0.13307247 | E31: =_xlfn.STDEV.S('Лист1 (2)'!F54, 'Лист1 (2)'!F69,'Лист1 (2)'!F84) -> 0.039961712 | F31: =_xlfn.STDEV.S('Лист1 (2)'!C99, 'Лист1 (2)'!D114,'Лист1 (2)'!D129) -> 0.070030083 | G31: =_xlfn.STDEV.S('Лист1 (2)'!F99, 'Лист1 (2)'!F114,'Лист1 (2)'!F129) -> 0.005766531 | H31: =_xlfn.STDEV.S('Лист1 (2)'!C144, 'Лист1 (2)'!D159,'Лист1 (2)'!D174) -> 0.075564037 | I31: =_xlfn.STDEV.S('Лист1 (2)'!F144, 'Лист1 (2)'!F159,'Лист1 (2)'!F174) -> 0.0091118199 | J31: =_xlfn.STDEV.S('Лист1 (2)'!C189, 'Лист1 (2)'!D204,'Лист1 (2)'!D219) -> 0.074495894 | K31: =_xlfn.STDEV.S('Лист1 (2)'!F189, 'Лист1 (2)'!F204,'Лист1 (2)'!F219) -> 0.043608588 | L31: =_xlfn.STDEV.S('Лист1 (2)'!C234, 'Лист1 (2)'!D249,'Лист1 (2)'!D264) -> 0.062297114 | M31: =_xlfn.STDEV.S('Лист1 (2)'!F234, 'Лист1 (2)'!F249,'Лист1 (2)'!F264) -> 0.024580499
A32: macular_hole | B32: =_xlfn.STDEV.S('Лист1 (2)'!D10, 'Лист1 (2)'!D25,'Лист1 (2)'!D40) -> 0.025468438 | C32: =_xlfn.STDEV.S('Лист1 (2)'!F10, 'Лист1 (2)'!F25,'Лист1 (2)'!F40) -> 0.011977185 | D32: =_xlfn.STDEV.S('Лист1 (2)'!C55, 'Лист1 (2)'!D70,'Лист1 (2)'!D85) -> 0.058485228 | E32: =_xlfn.STDEV.S('Лист1 (2)'!F55, 'Лист1 (2)'!F70,'Лист1 (2)'!F85) -> 0.013031913 | F32: =_xlfn.STDEV.S('Лист1 (2)'!C100, 'Лист1 (2)'!D115,'Лист1 (2)'!D130) -> 0.079784885 | G32: =_xlfn.STDEV.S('Лист1 (2)'!F100, 'Лист1 (2)'!F115,'Лист1 (2)'!F130) -> 0.014470956 | H32: =_xlfn.STDEV.S('Лист1 (2)'!C145, 'Лист1 (2)'!D160,'Лист1 (2)'!D175) -> 0.073334044 | I32: =_xlfn.STDEV.S('Лист1 (2)'!F145, 'Лист1 (2)'!F160,'Лист1 (2)'!F175) -> 0.014131648 | J32: =_xlfn.STDEV.S('Лист1 (2)'!C190, 'Лист1 (2)'!D205,'Лист1 (2)'!D220) -> 0.031382701 | K32: =_xlfn.STDEV.S('Лист1 (2)'!F190, 'Лист1 (2)'!F205,'Лист1 (2)'!F220) -> 0.011237555 | L32: =_xlfn.STDEV.S('Лист1 (2)'!C235, 'Лист1 (2)'!D250,'Лист1 (2)'!D265) -> 0.032738084 | M32: =_xlfn.STDEV.S('Лист1 (2)'!F235, 'Лист1 (2)'!F250,'Лист1 (2)'!F265) -> 0.014697561
A33: microaneurysms | B33: =_xlfn.STDEV.S('Лист1 (2)'!D11, 'Лист1 (2)'!D26,'Лист1 (2)'!D41) -> 0.021399831 | C33: =_xlfn.STDEV.S('Лист1 (2)'!F11, 'Лист1 (2)'!F26,'Лист1 (2)'!F41) -> 0.036121091 | D33: =_xlfn.STDEV.S('Лист1 (2)'!C56, 'Лист1 (2)'!D71,'Лист1 (2)'!D86) -> 0.042218282 | E33: =_xlfn.STDEV.S('Лист1 (2)'!F56, 'Лист1 (2)'!F71,'Лист1 (2)'!F86) -> 0.048016706 | F33: =_xlfn.STDEV.S('Лист1 (2)'!C101, 'Лист1 (2)'!D116,'Лист1 (2)'!D131) -> 0 | G33: =_xlfn.STDEV.S('Лист1 (2)'!F101, 'Лист1 (2)'!F116,'Лист1 (2)'!F131) -> 0 | H33: =_xlfn.STDEV.S('Лист1 (2)'!C146, 'Лист1 (2)'!D161,'Лист1 (2)'!D176) -> 0 | I33: =_xlfn.STDEV.S('Лист1 (2)'!F146, 'Лист1 (2)'!F161,'Лист1 (2)'!F176) -> 0 | J33: =_xlfn.STDEV.S('Лист1 (2)'!C191, 'Лист1 (2)'!D206,'Лист1 (2)'!D221) -> 0.077386282 | K33: =_xlfn.STDEV.S('Лист1 (2)'!F191, 'Лист1 (2)'!F206,'Лист1 (2)'!F221) -> 0.019782334 | L33: =_xlfn.STDEV.S('Лист1 (2)'!C236, 'Лист1 (2)'!D251,'Лист1 (2)'!D266) -> 0.078630397 | M33: =_xlfn.STDEV.S('Лист1 (2)'!F236, 'Лист1 (2)'!F251,'Лист1 (2)'!F266) -> 0.021501202
A34: neovascularization | B34: =_xlfn.STDEV.S('Лист1 (2)'!D12, 'Лист1 (2)'!D27,'Лист1 (2)'!D42) -> 0.0079154032 | C34: =_xlfn.STDEV.S('Лист1 (2)'!F12, 'Лист1 (2)'!F27,'Лист1 (2)'!F42) -> 0.038334481 | D34: =_xlfn.STDEV.S('Лист1 (2)'!C57, 'Лист1 (2)'!D72,'Лист1 (2)'!D87) -> 0.087116913 | E34: =_xlfn.STDEV.S('Лист1 (2)'!F57, 'Лист1 (2)'!F72,'Лист1 (2)'!F87) -> 0.028566896 | F34: =_xlfn.STDEV.S('Лист1 (2)'!C102, 'Лист1 (2)'!D117,'Лист1 (2)'!D132) -> 0.070368551 | G34: =_xlfn.STDEV.S('Лист1 (2)'!F102, 'Лист1 (2)'!F117,'Лист1 (2)'!F132) -> 0.014098983 | H34: =_xlfn.STDEV.S('Лист1 (2)'!C147, 'Лист1 (2)'!D162,'Лист1 (2)'!D177) -> 0.094587062 | I34: =_xlfn.STDEV.S('Лист1 (2)'!F147, 'Лист1 (2)'!F162,'Лист1 (2)'!F177) -> 0.036396757 | J34: =_xlfn.STDEV.S('Лист1 (2)'!C192, 'Лист1 (2)'!D207,'Лист1 (2)'!D222) -> 0.099528835 | K34: =_xlfn.STDEV.S('Лист1 (2)'!F192, 'Лист1 (2)'!F207,'Лист1 (2)'!F222) -> 0.0036518798 | L34: =_xlfn.STDEV.S('Лист1 (2)'!C237, 'Лист1 (2)'!D252,'Лист1 (2)'!D267) -> 0.10018828 | M34: =_xlfn.STDEV.S('Лист1 (2)'!F237, 'Лист1 (2)'!F252,'Лист1 (2)'!F267) -> 0.053745015
A35: soft_exudates | B35: =_xlfn.STDEV.S('Лист1 (2)'!D13, 'Лист1 (2)'!D28,'Лист1 (2)'!D43) -> 0.10758012 | C35: =_xlfn.STDEV.S('Лист1 (2)'!F13, 'Лист1 (2)'!F28,'Лист1 (2)'!F43) -> 0.15848712 | D35: =_xlfn.STDEV.S('Лист1 (2)'!C58, 'Лист1 (2)'!D73,'Лист1 (2)'!D88) -> 0.19256303 | E35: =_xlfn.STDEV.S('Лист1 (2)'!F58, 'Лист1 (2)'!F73,'Лист1 (2)'!F88) -> 0.13926616 | F35: =_xlfn.STDEV.S('Лист1 (2)'!C103, 'Лист1 (2)'!D118,'Лист1 (2)'!D133) -> 0.12202589 | G35: =_xlfn.STDEV.S('Лист1 (2)'!F103, 'Лист1 (2)'!F118,'Лист1 (2)'!F133) -> 0.15134784 | H35: =_xlfn.STDEV.S('Лист1 (2)'!C148, 'Лист1 (2)'!D163,'Лист1 (2)'!D178) -> 0.10776184 | I35: =_xlfn.STDEV.S('Лист1 (2)'!F148, 'Лист1 (2)'!F163,'Лист1 (2)'!F178) -> 0.17095071 | J35: =_xlfn.STDEV.S('Лист1 (2)'!C193, 'Лист1 (2)'!D208,'Лист1 (2)'!D223) -> 0.10400637 | K35: =_xlfn.STDEV.S('Лист1 (2)'!F193, 'Лист1 (2)'!F208,'Лист1 (2)'!F223) -> 0.15652448 | L35: =_xlfn.STDEV.S('Лист1 (2)'!C238, 'Лист1 (2)'!D253,'Лист1 (2)'!D268) -> 0.089480248 | M35: =_xlfn.STDEV.S('Лист1 (2)'!F238, 'Лист1 (2)'!F253,'Лист1 (2)'!F268) -> 0.15631793
... A37: venous_anomalies | B37: =_xlfn.STDEV.S('Лист1 (2)'!D15, 'Лист1 (2)'!D30,'Лист1 (2)'!D45) -> 0.20541643 | C37: =_xlfn.STDEV.S('Лист1 (2)'!F15, 'Лист1 (2)'!F30,'Лист1 (2)'!F45) -> 0.22335017 | D37: =_xlfn.STDEV.S('Лист1 (2)'!C60, 'Лист1 (2)'!D75,'Лист1 (2)'!D90) -> 0.25558927 | E37: =_xlfn.STDEV.S('Лист1 (2)'!F60, 'Лист1 (2)'!F75,'Лист1 (2)'!F90) -> 0.2557081 | F37: =_xlfn.STDEV.S('Лист1 (2)'!C105, 'Лист1 (2)'!D120,'Лист1 (2)'!D135) -> 0 | G37: =_xlfn.STDEV.S('Лист1 (2)'!F105, 'Лист1 (2)'!F120,'Лист1 (2)'!F135) -> 0 | H37: =_xlfn.STDEV.S('Лист1 (2)'!C150, 'Лист1 (2)'!D165,'Лист1 (2)'!D180) -> 0 | I37: =_xlfn.STDEV.S('Лист1 (2)'!F150, 'Лист1 (2)'!F165,'Лист1 (2)'!F180) -> 0 | J37: =_xlfn.STDEV.S('Лист1 (2)'!C195, 'Лист1 (2)'!D210,'Лист1 (2)'!D225) -> 0.11547593 | K37: =_xlfn.STDEV.S('Лист1 (2)'!F195, 'Лист1 (2)'!F210,'Лист1 (2)'!F225) -> 0.089300738 | L37: =_xlfn.STDEV.S('Лист1 (2)'!C240, 'Лист1 (2)'!D255,'Лист1 (2)'!D270) -> 0.18180285 | M37: =_xlfn.STDEV.S('Лист1 (2)'!F240, 'Лист1 (2)'!F255,'Лист1 (2)'!F270) -> 0.1470475

Sheet Лист2
B1: SegFormer | C1: Deeplab | D1: TransUnet
A2: IGNORE_INDEX | B2: 255 | C2: 255 | D2: 255
A3: PATCH_SIZE | B3: 512 | C3: 512 | D3: 512
A4: BATCH_SIZE | B4: 8 | C4: 8 | D4: 8
A5: EPOCHS | B5: 30 | C5: 30 | D5: 30
A6: Encoder lr | B6: 1e-05 | C6: 1e-05
A7: Decoder lr | B7: 0.0005 | C7: 0.0005
A8: Segmentation head lr | B8: - | C8: 0.0005
A9: lr | D9: 0.0001
A10: weight decay | D10: 0.0001
